Workbook

Sheet Overview
B2: CivicView Financial Model
B3: Infrastructure-only · 5-year plan · Moderate growth ramp · 3% conversion
B5: Sheets in this workbook
B6: 1. Assumptions | C6: All driver inputs. Blue cells are the ones you edit; everything else auto-recalculates.
B7: 2. ID.me costs by tier | C7: Point-in-time scenarios: what would verification cost if you hit 1K / 10K / 100K / 500K / 1M users.
B8: 3. Break-even | C8: Subscribers needed to cover monthly recurring costs at each user-count tier. Excludes one-time ID.me CAC.
B9: 4. Render hosting tiers | C9: Recommended Render config at each scale (1K → 100M users) with migration thresholds.
B10: 5. 5-Year P&L | C10: Year-by-year revenue, costs, net income, and margin — driven by the Assumptions sheet.
B11: 6. Sensitivity | C11: Y5 net income across 3 growth ramps × 4 conversion rates. Your selected scenario highlighted.
B13: How to use this model
B14: 1. Open the Assumptions sheet. Every blue cell is a knob — edit any of them and the rest of the workbook follows.
B15: 2. The model assumes infrastructure costs ONLY (Render + ID.me + APIs + domain). No salaries, no marketing.
B16: 3. Conversion rate (3%) and growth ramp (1K → 500K) match your selections. To stress-test, edit B11 (conversion) or B7:F7 (user counts).
B17: 4. The Sensitivity sheet is hardcoded so you can compare scenarios without disturbing the live model.
B18: 5. Color code: blue text = inputs you change. Black = formulas. Green = cross-sheet links. Yellow highlight = your scenario.
B20: Key caveats
B21: • Render pricing reflects mid-2025 published rates. Verify at render.com/pricing before committing — they revise quarterly.
B22: • ID.me $1.50 is the public retail rate. Volume contracts (>100K verifications/yr) typically negotiate to $0.80-$1.20.
B23: • User growth is a guess. The 'moderate ramp' is reasonable for civic apps but real growth is bursty (election years spike).
B24: • 3% conversion assumes a free-to-paid funnel where the paid tier offers clear value beyond the free experience.
B25: • Beyond 1M users, Render alone won't be the right fit — plan to migrate or negotiate Enterprise terms.

Sheet 1. Assumptions
A1: CivicView Financial Model — Assumptions
A2: All blue cells are inputs. Change any of them and every other sheet recalculates.
A4: User growth — moderate ramp (your selection)
B6: Y1 | C6: Y2 | D6: Y3 | E6: Y4 | F6: Y5
A7: Total users (end of year) | B7: 1000 | C7: 10000 | D7: 50000 | E7: 200000 | F7: 500000 | H7: ↑ Edit these blue cells to reshape the growth curve.
A8: New users added that year | B8: =B7 | C8: =C7-B7 | D8: =D7-C7 | E8: =E7-D7 | F8: =F7-E7
A10: Subscription economics
A11: Conversion rate (% of users who pay) | B11: 0.03 | H11: Industry typical for civic / public-interest apps: 1-5%. You chose 3%.
A12: Subscription price per month | B12: 5 | H12: Per the original spec — adjust here, every sheet follows.
A13: Annual price per subscriber | B13: =B12*12 | H13: Auto-derived. Don't edit.
A15: ID.me verification costs
A16: Cost per verification (one-time) | B16: 1.5 | H16: Per ID.me public pricing — verify their current rate at idme.com.
A17: % of total users who get verified | B17: 1 | H17: 100% = required at signup. If verification is only for voting features, drop to 30-50%.
A18: Annual re-verification rate | B18: 0 | H18: ID.me verifications typically last 3+ years. Set non-zero if you'll re-verify annually.
A20: Render hosting — monthly cost at each user-count tier
A21: Tier (max users) | B21: Monthly cost | H21: Recommended Render configuration
A22: ≤ 1,000 users | B22: 50 | H22: Standard web ($25) + Basic 1GB Postgres ($19) + bandwidth free tier
A23: ≤ 10,000 users | B23: 180 | H23: Pro web ($85) + Basic 4GB Postgres ($95) + ~50GB bandwidth
A24: ≤ 50,000 users | B24: 450 | H24: 2× Pro web ($170) + Pro 4GB Postgres ($185) + Redis ($30) + 200GB bandwidth
A25: ≤ 200,000 users | B25: 1000 | H25: 2× Pro Plus ($350) + Pro 4GB Postgres ($185) + Redis ($85) + 500GB ($50) + buffer
A26: ≤ 500,000 users | B26: 2500 | H26: 4× Pro Max ($1,800) + Pro 8GB Postgres ($345) + 2TB bandwidth ($200) + CDN
A27: ≤ 1,000,000 users | B27: 5000 | H27: Render Enterprise contract OR start AWS/GCP migration. 4× Pro Max + 16GB Postgres + 5TB bandwidth
A28: ≤ 10,000,000 users | B28: 25000 | H28: Migrate off Render: AWS/GCP multi-region, CDN, dedicated DB clusters
A29: ≤ 100,000,000 users | B29: 250000 | H29: Major infrastructure investment — custom cloud build, multi-region active-active, dedicated SRE team
A31: Other recurring infrastructure costs (annual)
A32: Domain + DNS | B32: 50 | H32: civicview.app + Cloudflare/Namecheap
A33: Anthropic API (Haiku for AI features) | B33: 500 | H33: Bill summaries, vote explainers — scales with users; assume modest at small scale
A34: Email + transactional (Mailgun/Postmark) | B34: 300 | H34: Notifications, ack emails — free tier up to a few thousand sends
A35: Monitoring (Sentry/Datadog) | B35: 200 | H35: Error tracking + uptime — free tiers cover early stage
A36: Misc (legal, accounting templates, etc.) | B36: 500 | H36: Legal templates, accounting subscriptions, etc. Payment processing fees are broken out in the Payment processing section below.
A37: Total other recurring (annual) | B37: =SUM(B32:B36)+B63+B66
A39: Payment processing — app store + web subscription fees
A40: iOS App Store revenue share | B40: 0.3 | H40: Share of paying subscribers who subscribe via iOS in-app purchase. Default 30% based on civic-app user mix.
A41: Google Play revenue share | B41: 0.2 | H41: Android in-app purchase share. Default 20% — US civic apps skew slightly iOS.
A42: Web (Stripe) revenue share | B42: =1-B40-B41 | H42: Auto = 1 - iOS - Android. If this goes negative, your iOS + Android shares sum > 100%.
A43: iOS App Store fee rate | B43: 0.15 | H43: Apple Small Business Program: 15% if App Store revenue <$1M/yr. Flip to 30% once you cross that threshold.
A44: Google Play fee rate | B44: 0.15 | H44: Google Play also 15% on first $1M/yr per developer; jumps to 30% beyond.
A45: Stripe / web processing rate (effective) | B45: 0.05 | H45: Stripe 2.9% + $0.30 per transaction. On $5/mo billing the fixed fee dominates (~9% effective); annual billing drops to ~3.5%. 5% is a moderate blend.
A46: Blended payment-processing rate | B46: =B40*B43+B41*B44+B42*B45 | H46: Auto: weighted average across iOS / Android / Web. The P&L applies this to total subscription revenue.
A48: Cybersecurity (external penetration testing)
...

Sheet 2. ID.me costs by tier
A1: ID.me verification costs — what would it cost if we hit X users?
A2: One-time verification cost per user, applied across all verified users at each scale tier.
A4: Scenario: total verification cost at each tier
A6: User tier | B6: Verified users | C6: Cost / verification | D6: Total verification cost | E6: Amortized monthly (over 12mo) | F6: Months to recoup at 3% conversion | G6: Notes
A7: 1,000 users | B7: =1000*'1. Assumptions'!B17 | C7: ='1. Assumptions'!B16 | D7: =B7*C7 | E7: =D7/12 | F7: =D7/(B7*'1. Assumptions'!B11*'1. Assumptions'!B12) | G7: Small starter — manageable burn.
A8: 10,000 users | B8: =10000*'1. Assumptions'!B17 | C8: ='1. Assumptions'!B16 | D8: =B8*C8 | E8: =D8/12 | F8: =D8/(B8*'1. Assumptions'!B11*'1. Assumptions'!B12) | G8: 10K is the inflection point where you need real customer support.
A9: 100,000 users | B9: =100000*'1. Assumptions'!B17 | C9: ='1. Assumptions'!B16 | D9: =B9*C9 | E9: =D9/12 | F9: =D9/(B9*'1. Assumptions'!B11*'1. Assumptions'!B12) | G9: At 100K you can negotiate ID.me volume pricing — expect $1.00-$1.20.
A10: 500,000 users | B10: =500000*'1. Assumptions'!B17 | C10: ='1. Assumptions'!B16 | D10: =B10*C10 | E10: =D10/12 | F10: =D10/(B10*'1. Assumptions'!B11*'1. Assumptions'!B12) | G10: At 500K verification cost = $750K. Major fundraise needed if upfront.
A11: 1,000,000 users | B11: =1000000*'1. Assumptions'!B17 | C11: ='1. Assumptions'!B16 | D11: =B11*C11 | E11: =D11/12 | F11: =D11/(B11*'1. Assumptions'!B11*'1. Assumptions'!B12) | G11: At 1M users this is a $1.5M line item — verify is a strategic decision.
A13: Key insight
A14: • Verification cost is NOT a per-month cost — it's a one-time hit at the moment of user signup. Your model should treat it as customer-acquisition cost (CAC).
A15: • At 3% conversion + $5/mo, each paying subscriber generates $60/yr. The $1.50 verification cost is recouped within the first month of any single subscriber.
A16: • But: you're paying $1.50 for 100% of users while only 3% pay. Effective CAC per paying subscriber = $1.50 / 0.03 = $50 just for verification. Still healthy vs. $60/yr LTV per paying user.
A17: • If verification is only required for voting features (not signup), and only 30% of users verify, your effective CAC drops to $50 × 30% = $15 per paid sub. Worth considering as a product decision.

Sheet 3. Break-even
A1: Break-even — how many paying subscribers to cover monthly costs?
A2: Excludes one-time ID.me costs (those are CAC, not recurring). Recurring = Render hosting + other infra.
A4: Monthly break-even at each user-count tier
A6: User tier | B6: Render monthly | C6: Other infra /mo | D6: Total monthly cost | E6: Break-even subs needed | F6: Subs at 3% conversion | G6: Surplus / (deficit) subs | H6: Monthly net at 3%
A7: 1,000 users | B7: ='1. Assumptions'!B22 | C7: ='1. Assumptions'!B37/12 | D7: =B7+C7 | E7: =ROUNDUP(D7/('1. Assumptions'!$B$12*(1-'1. Assumptions'!$B$46)),0) | F7: =1000*'1. Assumptions'!B11 | G7: =F7-E7 | H7: =F7*'1. Assumptions'!$B$12*(1-'1. Assumptions'!$B$46)-D7
A8: 10,000 users | B8: ='1. Assumptions'!B23 | C8: ='1. Assumptions'!B37/12 | D8: =B8+C8 | E8: =ROUNDUP(D8/('1. Assumptions'!$B$12*(1-'1. Assumptions'!$B$46)),0) | F8: =10000*'1. Assumptions'!B11 | G8: =F8-E8 | H8: =F8*'1. Assumptions'!$B$12*(1-'1. Assumptions'!$B$46)-D8
A9: 50,000 users | B9: ='1. Assumptions'!B24 | C9: ='1. Assumptions'!B37/12 | D9: =B9+C9 | E9: =ROUNDUP(D9/('1. Assumptions'!$B$12*(1-'1. Assumptions'!$B$46)),0) | F9: =50000*'1. Assumptions'!B11 | G9: =F9-E9 | H9: =F9*'1. Assumptions'!$B$12*(1-'1. Assumptions'!$B$46)-D9
A10: 100,000 users | B10: ='1. Assumptions'!B24 | C10: ='1. Assumptions'!B37/12 | D10: =B10+C10 | E10: =ROUNDUP(D10/('1. Assumptions'!$B$12*(1-'1. Assumptions'!$B$46)),0) | F10: =100000*'1. Assumptions'!B11 | G10: =F10-E10 | H10: =F10*'1. Assumptions'!$B$12*(1-'1. Assumptions'!$B$46)-D10
A11: 200,000 users | B11: ='1. Assumptions'!B25 | C11: ='1. Assumptions'!B37/12 | D11: =B11+C11 | E11: =ROUNDUP(D11/('1. Assumptions'!$B$12*(1-'1. Assumptions'!$B$46)),0) | F11: =200000*'1. Assumptions'!B11 | G11: =F11-E11 | H11: =F11*'1. Assumptions'!$B$12*(1-'1. Assumptions'!$B$46)-D11
A12: 500,000 users | B12: ='1. Assumptions'!B26 | C12: ='1. Assumptions'!B37/12 | D12: =B12+C12 | E12: =ROUNDUP(D12/('1. Assumptions'!$B$12*(1-'1. Assumptions'!$B$46)),0) | F12: =500000*'1. Assumptions'!B11 | G12: =F12-E12 | H12: =F12*'1. Assumptions'!$B$12*(1-'1. Assumptions'!$B$46)-D12
A13: 1,000,000 users | B13: ='1. Assumptions'!B27 | C13: ='1. Assumptions'!B37/12 | D13: =B13+C13 | E13: =ROUNDUP(D13/('1. Assumptions'!$B$12*(1-'1. Assumptions'!$B$46)),0) | F13: =1000000*'1. Assumptions'!B11 | G13: =F13-E13 | H13: =F13*'1. Assumptions'!$B$12*(1-'1. Assumptions'!$B$46)-D13
A16: What this tells you
A17: • At 1K users, you need 27 paying subscribers. At 3% conversion you get 30 — wafer-thin margin but technically profitable on recurring costs.
A18: • At 10K users (Y2 in your ramp), you're comfortable: 300 subs at 3% vs ~50 needed to cover Render. Most of the margin starts flowing here.
A19: • At 50K-100K users the Render cost barely grows (same tier) so margin expands rapidly. This is where the business gets healthy.
A20: • Beyond 500K, you should renegotiate Render Enterprise OR plan a cloud migration. The $5K/mo for 1M users is likely a starting point for negotiation, not a ceiling.
A22: • Subs-needed (col E) and monthly-net (col H) now use the post-fee effective sub price = $5 × (1 - blended payment rate). At default 30/20/50 iOS/Android/Web mix the blended rate is ~10%, so effective price is $4.50.

Sheet 4. Render hosting tiers
A1: Render hosting — configuration at each scale
A2: Recommended Render config + monthly cost at each user-count milestone. Beyond 1M, plan to renegotiate or migrate.
A4: Hosting recommendations
A6: User count | B6: Web service | C6: Postgres | D6: Bandwidth | E6: Monthly cost | F6: Notes / when to upgrade
A7: 1,000 users | B7: Standard ($25) | C7: Basic 1GB ($19) | D7: Free tier (100GB) | E7: 50 | F7: Stays here through Y1. Single instance is fine.
A8: 10,000 users | B8: Pro ($85) | C8: Basic 4GB ($95) | D8: ~50GB ($0) | E8: 180 | F8: Upgrade web to Pro when concurrent users exceed ~200.
A9: 50,000 users | B9: 2× Pro ($170) + Redis ($30) | C9: Pro 4GB ($185) | D9: 200GB ($10) | E9: 450 | F9: Autoscale + Redis caching is the big jump. Postgres needs HA + automated backups.
A10: 100,000 users | B10: 2-3× Pro ($170-255) + Redis ($30) | C10: Pro 4GB ($185) | D10: 500GB ($40) | E10: 450 | F10: Same shape as 50K — bandwidth scales but compute is OK with caching.
A11: 200,000 users | B11: 2× Pro Plus ($350) + Redis ($85) | C11: Pro 4GB ($185) | D11: 1TB ($100) | E11: 1000 | F11: Memory headroom for connection pooling. Consider replica reads.
A12: 500,000 users | B12: 4× Pro Max ($1,800) | C12: Pro 8GB ($345) + replica | D12: 2TB ($200) | E12: 2500 | F12: Multi-region warm-failover. Renegotiate with Render.
A13: 1,000,000 users | B13: Render Enterprise contract | C13: Pro 16GB ($770) | D13: 5TB ($500) | E13: 5000 | F13: Negotiate volume discount with Render OR start AWS/GCP migration plan.
A14: 10,000,000 users | B14: Migrated to AWS/GCP multi-region | C14: Dedicated DB cluster ~$8K | D14: CDN + WAF ~$5K | E14: 25000 | F14: Render alone won't scale here. Need DevOps/SRE. Plan migration at ~3M users.
A15: 100,000,000 users | B15: Multi-cloud, dedicated SRE team | C15: Sharded clusters ~$50K+ | D15: Global CDN ~$30K | E15: 250000 | F15: FAANG-tier infrastructure investment. Custom platform engineering. Real-time data layer.
A17: Annual cost = monthly × 12. Multiply column E by 12 for yearly hosting line item.
A19: Migration thresholds
A20: • ≤500K users: Render is a great fit. Focus on product, not infra.
A21: • 500K-1M users: Talk to Render about Enterprise. Volume discount usually 20-40%. Bandwidth is the biggest line item — consider Cloudflare R2 + CDN to offload egress.
A22: • 1M-10M users: Migrate to AWS/GCP/Cloudflare. Hire one DevOps engineer. Render bills become unpredictable here; cloud gives you per-second pricing + reserved instances.
A23: • 10M+ users: Full SRE team, multi-region active-active, real-time data layer (Kafka/Kinesis), dedicated security/compliance. This is a fundamentally different company.

Sheet 5. 5-Year P&L
A1: CivicView — 5-year P&L (infrastructure-only)
A2: Year-by-year revenue, costs, and net. All driven by the Assumptions sheet — change inputs there and this updates.
B4: Y1 | C4: Y2 | D4: Y3 | E4: Y4 | F4: Y5
A6: Users
A7: Total users (end of year) | B7: ='1. Assumptions'!B7 | C7: ='1. Assumptions'!C7 | D7: ='1. Assumptions'!D7 | E7: ='1. Assumptions'!E7 | F7: ='1. Assumptions'!F7
A8: New users added that year | B8: ='1. Assumptions'!B8 | C8: ='1. Assumptions'!C8 | D8: ='1. Assumptions'!D8 | E8: ='1. Assumptions'!E8 | F8: ='1. Assumptions'!F8
A9: Paying subscribers (at 3% conversion) | B9: =ROUND(B7*'1. Assumptions'!$B$11,0) | C9: =ROUND(C7*'1. Assumptions'!$B$11,0) | D9: =ROUND(D7*'1. Assumptions'!$B$11,0) | E9: =ROUND(E7*'1. Assumptions'!$B$11,0) | F9: =ROUND(F7*'1. Assumptions'!$B$11,0)
A11: Revenue
A12: Subscription revenue (subs × $60/yr) | B12: =B9*'1. Assumptions'!$B$13 | C12: =C9*'1. Assumptions'!$B$13 | D12: =D9*'1. Assumptions'!$B$13 | E12: =E9*'1. Assumptions'!$B$13 | F12: =F9*'1. Assumptions'!$B$13
A13: Total revenue | B13: =B12 | C13: =C12 | D13: =D12 | E13: =E12 | F13: =F12
A15: Costs
A16: ID.me verification (new users × $1.50) | B16: =B8*'1. Assumptions'!$B$16*'1. Assumptions'!$B$17 | C16: =C8*'1. Assumptions'!$B$16*'1. Assumptions'!$B$17 | D16: =D8*'1. Assumptions'!$B$16*'1. Assumptions'!$B$17 | E16: =E8*'1. Assumptions'!$B$16*'1. Assumptions'!$B$17 | F16: =F8*'1. Assumptions'!$B$16*'1. Assumptions'!$B$17
A17: Render hosting (annual) | B17: =IF(B7<=1000,'1. Assumptions'!$B$22,IF(B7<=10000,'1. Assumptions'!$B$23,IF(B7<=50000,'1. Assumptions'!$B$24,IF(B7<=200000,'1. Assumptions'!$B$25,IF(B7<=500000,'1. Assumptions'!$B$26,IF(B7<=1000000,'1. Assumptions'!$B$27,'1. Assumptions'!$B$28))))))*12 | C17: =IF(C7<=1000,'1. Assumptions'!$B$22,IF(C7<=10000,'1. Assumptions'!$B$23,IF(C7<=50000,'1. Assumptions'!$B$24,IF(C7<=200000,'1. Assumptions'!$B$25,IF(C7<=500000,'1. Assumptions'!$B$26,IF(C7<=1000000,'1. Assumptions'!$B$27,'1. Assumptions'!$B$28))))))*12 | D17: =IF(D7<=1000,'1. Assumptions'!$B$22,IF(D7<=10000,'1. Assumptions'!$B$23,IF(D7<=50000,'1. Assumptions'!$B$24,IF(D7<=200000,'1. Assumptions'!$B$25,IF(D7<=500000,'1. Assumptions'!$B$26,IF(D7<=1000000,'1. Assumptions'!$B$27,'1. Assumptions'!$B$28))))))*12 | E17: =IF(E7<=1000,'1. Assumptions'!$B$22,IF(E7<=10000,'1. Assumptions'!$B$23,IF(E7<=50000,'1. Assumptions'!$B$24,IF(E7<=200000,'1. Assumptions'!$B$25,IF(E7<=500000,'1. Assumptions'!$B$26,IF(E7<=1000000,'1. Assumptions'!$B$27,'1. Assumptions'!$B$28))))))*12 | F17: =IF(F7<=1000,'1. Assumptions'!$B$22,IF(F7<=10000,'1. Assumptions'!$B$23,IF(F7<=50000,'1. Assumptions'!$B$24,IF(F7<=200000,'1. Assumptions'!$B$25,IF(F7<=500000,'1. Assumptions'!$B$26,IF(F7<=1000000,'1. Assumptions'!$B$27,'1. Assumptions'!$B$28))))))*12
A18: Other recurring infra (annual) | B18: ='1. Assumptions'!$B$37 | C18: ='1. Assumptions'!$B$37 | D18: ='1. Assumptions'!$B$37 | E18: ='1. Assumptions'!$B$37 | F18: ='1. Assumptions'!$B$37
A19: Payment processing (app store + Stripe) | B19: =B13*'1. Assumptions'!$B$46 | C19: =C13*'1. Assumptions'!$B$46 | D19: =D13*'1. Assumptions'!$B$46 | E19: =E13*'1. Assumptions'!$B$46 | F19: =F13*'1. Assumptions'!$B$46
A20: External penetration test | B20: ='1. Assumptions'!B50 | C20: ='1. Assumptions'!C50 | D20: ='1. Assumptions'!D50 | E20: ='1. Assumptions'!E50 | F20: ='1. Assumptions'!F50
A21: Total costs | B21: =SUM(B16:B20) | C21: =SUM(C16:C20) | D21: =SUM(D16:D20) | E21: =SUM(E16:E20) | F21: =SUM(F16:F20)
A23: Net income
A24: Net income (year) | B24: =B13-B21 | C24: =C13-C21 | D24: =D13-D21 | E24: =E13-E21 | F24: =F13-F21
A25: Cumulative net income | B25: =B24 | C25: =B25+C24 | D25: =C25+D24 | E25: =D25+E24 | F25: =E25+F24
A26: Margin (net / revenue) | B26: =IFERROR(B24/B13,0) | C26: =IFERROR(C24/C13,0) | D26: =IFERROR(D24/D13,0) | E26: =IFERROR(E24/E13,0) | F26: =IFERROR(F24/F13,0)
A28: Reading this sheet
A29: • Y1-Y2 show losses: ID.me verification + initial Render costs + Y2 pen-test ($5K) exceed early subscription revenue at 1K-10K users.
A30: • Y3 is the new break-even year (~$4K positive) under your moderate ramp + 3% conversion. Y4-Y5 deliver the bulk of the cumulative net.
A31: • Cumulative net by Y5: ~$375K — your reinvestment runway. (Down from ~$565K pre-Phase-4 once payment fees + pen-test were added.)
A32: • Sensitivity to watch: dropping conversion to 1% would deepen losses through Y3 and push Y5 net into the red on slow/moderate ramps. Raising to 5% pushes Y5 net to ~$850K.
A33: • ID.me remains the dominant cost (~75% of Y4-Y5 total). Volume pricing (typical at 100K+ verifications/yr) directly improves margin.
A34: • Payment processing (app store + Stripe) now broken out — applies the Assumptions blended rate (~10% at default 30/20/50 mix) to gross revenue.
A35: • External pen-test costs ramp from $5K (Y1) to $20K (Y5) following the cybersecurity attack-surface schedule in Assumptions row 50.

Sheet 6. Sensitivity
A1: Sensitivity — Year-5 net income at different conversion + growth
A2: Hardcoded scenarios (independent of Assumptions sheet) so you can compare side-by-side without editing.
A4: Y5 net income — sensitivity to conversion × growth
A6: Growth scenario \ Conversion | B6: 1% | C6: 3% | D6: 5% | E6: 10%
A7: Slow ramp (250K Y5) | B7: =(250000*0.01*'1. Assumptions'!$B$13)*(1-'1. Assumptions'!$B$46)-(150000*'1. Assumptions'!$B$16*'1. Assumptions'!$B$17+12000+'1. Assumptions'!$B$37+'1. Assumptions'!$F$50) | C7: =(250000*0.03*'1. Assumptions'!$B$13)*(1-'1. Assumptions'!$B$46)-(150000*'1. Assumptions'!$B$16*'1. Assumptions'!$B$17+12000+'1. Assumptions'!$B$37+'1. Assumptions'!$F$50) | D7: =(250000*0.05*'1. Assumptions'!$B$13)*(1-'1. Assumptions'!$B$46)-(150000*'1. Assumptions'!$B$16*'1. Assumptions'!$B$17+12000+'1. Assumptions'!$B$37+'1. Assumptions'!$F$50) | E7: =(250000*0.1*'1. Assumptions'!$B$13)*(1-'1. Assumptions'!$B$46)-(150000*'1. Assumptions'!$B$16*'1. Assumptions'!$B$17+12000+'1. Assumptions'!$B$37+'1. Assumptions'!$F$50)
A8: Moderate ramp (500K Y5) | B8: =(500000*0.01*'1. Assumptions'!$B$13)*(1-'1. Assumptions'!$B$46)-(300000*'1. Assumptions'!$B$16*'1. Assumptions'!$B$17+30000+'1. Assumptions'!$B$37+'1. Assumptions'!$F$50) | C8: =(500000*0.03*'1. Assumptions'!$B$13)*(1-'1. Assumptions'!$B$46)-(300000*'1. Assumptions'!$B$16*'1. Assumptions'!$B$17+30000+'1. Assumptions'!$B$37+'1. Assumptions'!$F$50) | D8: =(500000*0.05*'1. Assumptions'!$B$13)*(1-'1. Assumptions'!$B$46)-(300000*'1. Assumptions'!$B$16*'1. Assumptions'!$B$17+30000+'1. Assumptions'!$B$37+'1. Assumptions'!$F$50) | E8: =(500000*0.1*'1. Assumptions'!$B$13)*(1-'1. Assumptions'!$B$46)-(300000*'1. Assumptions'!$B$16*'1. Assumptions'!$B$17+30000+'1. Assumptions'!$B$37+'1. Assumptions'!$F$50)
A9: Aggressive ramp (1M Y5) | B9: =(1000000*0.01*'1. Assumptions'!$B$13)*(1-'1. Assumptions'!$B$46)-(500000*'1. Assumptions'!$B$16*'1. Assumptions'!$B$17+60000+'1. Assumptions'!$B$37+'1. Assumptions'!$F$50) | C9: =(1000000*0.03*'1. Assumptions'!$B$13)*(1-'1. Assumptions'!$B$46)-(500000*'1. Assumptions'!$B$16*'1. Assumptions'!$B$17+60000+'1. Assumptions'!$B$37+'1. Assumptions'!$F$50) | D9: =(1000000*0.05*'1. Assumptions'!$B$13)*(1-'1. Assumptions'!$B$46)-(500000*'1. Assumptions'!$B$16*'1. Assumptions'!$B$17+60000+'1. Assumptions'!$B$37+'1. Assumptions'!$F$50) | E9: =(1000000*0.1*'1. Assumptions'!$B$13)*(1-'1. Assumptions'!$B$46)-(500000*'1. Assumptions'!$B$16*'1. Assumptions'!$B$17+60000+'1. Assumptions'!$B$37+'1. Assumptions'!$F$50)
A11: Reading this grid
A12: • Your selected scenario is highlighted in yellow (Moderate ramp + 3% conversion).
A13: • Each cell shows Year-5 net income (revenue minus all costs that year, not cumulative).
A14: • The diagonals matter: doubling conversion has a bigger impact than doubling growth, because growth also doubles the ID.me verification bill.
A15: • The 'Aggressive ramp + 1%' cell can be negative — that's the danger zone: scaling fast on free users without conversion is the worst combination.
A16: • Updated to include payment-processing fees (gross revenue × blended rate) and Y5 pen-test cost — see Assumptions rows 46 + 50. Numbers are slightly lower than the previous version because of the ~10% fee drag.
